<?xml version="1.0" encoding="UTF-8"?>
<testng-results ignored="0" total="7" passed="2" failed="5" skipped="0">
  <reporter-output>
  </reporter-output>
  <suite started-at="2021-01-26T14:22:27Z" name="Suite" finished-at="2021-01-26T14:22:33Z" duration-ms="5240">
    <groups>
    </groups>
    <test started-at="2021-01-26T14:22:27Z" name="EOAPITest" finished-at="2021-01-26T14:22:33Z" duration-ms="5240">
      <class name="com.eo.tests.PostNewUser">
        <test-method signature="createNewUser_TC004(java.lang.String, java.lang.String)[pri:0, instance:com.eo.tests.PostNewUser@c7045b9]" started-at="2021-01-26T14:22:32Z" name="createNewUser_TC004" data-provider="getUserData" finished-at="2021-01-26T14:22:32Z" duration-ms="285" status="PASS">
          <params>
            <param index="0">
              <value>
                <![CDATA[xyz]]>
              </value>
            </param>
            <param index="1">
              <value>
                <![CDATA[tester]]>
              </value>
            </param>
          </params>
          <reporter-output>
          </reporter-output>
        </test-method> <!-- createNewUser_TC004 -->
        <test-method is-config="true" signature="setUp()[pri:0, instance:com.eo.tests.PostNewUser@c7045b9]" started-at="2021-01-26T14:22:32Z" name="setUp" finished-at="2021-01-26T14:22:32Z" duration-ms="0" status="PASS">
          <reporter-output>
          </reporter-output>
        </test-method> <!-- setUp -->
        <test-method is-config="true" signature="setUp()[pri:0, instance:com.eo.tests.PostNewUser@c7045b9]" started-at="2021-01-26T14:22:32Z" name="setUp" finished-at="2021-01-26T14:22:32Z" duration-ms="5" status="PASS">
          <reporter-output>
          </reporter-output>
        </test-method> <!-- setUp -->
        <test-method signature="createNewUserIncorrectEP_TC005()[pri:1, instance:com.eo.tests.PostNewUser@c7045b9]" started-at="2021-01-26T14:22:32Z" name="createNewUserIncorrectEP_TC005" finished-at="2021-01-26T14:22:32Z" duration-ms="159" status="FAIL">
          <exception class="java.lang.AssertionError">
            <message>
              <![CDATA[expected [201] but found [404]]]>
            </message>
            <full-stacktrace>
              <![CDATA[java.lang.AssertionError: expected [201] but found [404]
at org.testng.Assert.fail(Assert.java:96)
at org.testng.Assert.failNotEquals(Assert.java:776)
at org.testng.Assert.assertEqualsImpl(Assert.java:137)
at org.testng.Assert.assertEquals(Assert.java:118)
at org.testng.Assert.assertEquals(Assert.java:652)
at org.testng.Assert.assertEquals(Assert.java:662)
at com.eo.tests.PostNewUser.createNewUserIncorrectEP_TC005(PostNewUser.java:81)
at java.base/jdk.internal.reflect.NativeMethodAccessorImpl.invoke0(Native Method)
at java.base/jdk.internal.reflect.NativeMethodAccessorImpl.invoke(NativeMethodAccessorImpl.java:62)
at java.base/jdk.internal.reflect.DelegatingMethodAccessorImpl.invoke(DelegatingMethodAccessorImpl.java:43)
at java.base/java.lang.reflect.Method.invoke(Method.java:566)
at org.testng.internal.MethodInvocationHelper.invokeMethod(MethodInvocationHelper.java:124)
at org.testng.internal.Invoker.invokeMethod(Invoker.java:583)
at org.testng.internal.Invoker.invokeTestMethod(Invoker.java:719)
at org.testng.internal.Invoker.invokeTestMethods(Invoker.java:989)
at org.testng.internal.TestMethodWorker.invokeTestMethods(TestMethodWorker.java:125)
at org.testng.internal.TestMethodWorker.run(TestMethodWorker.java:109)
at org.testng.TestRunner.privateRun(TestRunner.java:648)
at org.testng.TestRunner.run(TestRunner.java:505)
at org.testng.SuiteRunner.runTest(SuiteRunner.java:455)
at org.testng.SuiteRunner.runSequentially(SuiteRunner.java:450)
at org.testng.SuiteRunner.privateRun(SuiteRunner.java:415)
at org.testng.SuiteRunner.run(SuiteRunner.java:364)
at org.testng.SuiteRunnerWorker.runSuite(SuiteRunnerWorker.java:52)
at org.testng.SuiteRunnerWorker.run(SuiteRunnerWorker.java:84)
at org.testng.TestNG.runSuitesSequentially(TestNG.java:1208)
at org.testng.TestNG.runSuitesLocally(TestNG.java:1137)
at org.testng.TestNG.runSuites(TestNG.java:1049)
at org.testng.TestNG.run(TestNG.java:1017)
at org.testng.remote.AbstractRemoteTestNG.run(AbstractRemoteTestNG.java:115)
at org.testng.remote.RemoteTestNG.initAndRun(RemoteTestNG.java:251)
at org.testng.remote.RemoteTestNG.main(RemoteTestNG.java:77)
]]>
            </full-stacktrace>
          </exception> <!-- java.lang.AssertionError -->
          <reporter-output>
          </reporter-output>
        </test-method> <!-- createNewUserIncorrectEP_TC005 -->
        <test-method is-config="true" signature="setUp()[pri:0, instance:com.eo.tests.PostNewUser@c7045b9]" started-at="2021-01-26T14:22:32Z" name="setUp" finished-at="2021-01-26T14:22:32Z" duration-ms="0" status="PASS">
          <reporter-output>
          </reporter-output>
        </test-method> <!-- setUp -->
        <test-method signature="createNewUserIncorrectParamValuesInteger_TC006()[pri:2, instance:com.eo.tests.PostNewUser@c7045b9]" started-at="2021-01-26T14:22:32Z" name="createNewUserIncorrectParamValuesInteger_TC006" finished-at="2021-01-26T14:22:32Z" duration-ms="168" status="FAIL">
          <exception class="java.lang.AssertionError">
            <message>
              <![CDATA[expected [201] but found [400]]]>
            </message>
            <full-stacktrace>
              <![CDATA[java.lang.AssertionError: expected [201] but found [400]
at org.testng.Assert.fail(Assert.java:96)
at org.testng.Assert.failNotEquals(Assert.java:776)
at org.testng.Assert.assertEqualsImpl(Assert.java:137)
at org.testng.Assert.assertEquals(Assert.java:118)
at org.testng.Assert.assertEquals(Assert.java:652)
at org.testng.Assert.assertEquals(Assert.java:662)
at com.eo.tests.PostNewUser.createNewUserIncorrectParamValuesInteger_TC006(PostNewUser.java:105)
at java.base/jdk.internal.reflect.NativeMethodAccessorImpl.invoke0(Native Method)
at java.base/jdk.internal.reflect.NativeMethodAccessorImpl.invoke(NativeMethodAccessorImpl.java:62)
at java.base/jdk.internal.reflect.DelegatingMethodAccessorImpl.invoke(DelegatingMethodAccessorImpl.java:43)
at java.base/java.lang.reflect.Method.invoke(Method.java:566)
at org.testng.internal.MethodInvocationHelper.invokeMethod(MethodInvocationHelper.java:124)
at org.testng.internal.Invoker.invokeMethod(Invoker.java:583)
at org.testng.internal.Invoker.invokeTestMethod(Invoker.java:719)
at org.testng.internal.Invoker.invokeTestMethods(Invoker.java:989)
at org.testng.internal.TestMethodWorker.invokeTestMethods(TestMethodWorker.java:125)
at org.testng.internal.TestMethodWorker.run(TestMethodWorker.java:109)
at org.testng.TestRunner.privateRun(TestRunner.java:648)
at org.testng.TestRunner.run(TestRunner.java:505)
at org.testng.SuiteRunner.runTest(SuiteRunner.java:455)
at org.testng.SuiteRunner.runSequentially(SuiteRunner.java:450)
at org.testng.SuiteRunner.privateRun(SuiteRunner.java:415)
at org.testng.SuiteRunner.run(SuiteRunner.java:364)
at org.testng.SuiteRunnerWorker.runSuite(SuiteRunnerWorker.java:52)
at org.testng.SuiteRunnerWorker.run(SuiteRunnerWorker.java:84)
at org.testng.TestNG.runSuitesSequentially(TestNG.java:1208)
at org.testng.TestNG.runSuitesLocally(TestNG.java:1137)
at org.testng.TestNG.runSuites(TestNG.java:1049)
at org.testng.TestNG.run(TestNG.java:1017)
at org.testng.remote.AbstractRemoteTestNG.run(AbstractRemoteTestNG.java:115)
at org.testng.remote.RemoteTestNG.initAndRun(RemoteTestNG.java:251)
at org.testng.remote.RemoteTestNG.main(RemoteTestNG.java:77)
]]>
            </full-stacktrace>
          </exception> <!-- java.lang.AssertionError -->
          <reporter-output>
          </reporter-output>
        </test-method> <!-- createNewUserIncorrectParamValuesInteger_TC006 -->
        <test-method is-config="true" signature="setUp()[pri:0, instance:com.eo.tests.PostNewUser@c7045b9]" started-at="2021-01-26T14:22:33Z" name="setUp" finished-at="2021-01-26T14:22:33Z" duration-ms="0" status="PASS">
          <reporter-output>
          </reporter-output>
        </test-method> <!-- setUp -->
        <test-method signature="createNewUserIncorrectParamValuesSpecChar_TC007()[pri:3, instance:com.eo.tests.PostNewUser@c7045b9]" started-at="2021-01-26T14:22:33Z" name="createNewUserIncorrectParamValuesSpecChar_TC007" finished-at="2021-01-26T14:22:33Z" duration-ms="152" status="FAIL">
          <exception class="java.lang.AssertionError">
            <message>
              <![CDATA[expected [201] but found [400]]]>
            </message>
            <full-stacktrace>
              <![CDATA[java.lang.AssertionError: expected [201] but found [400]
at org.testng.Assert.fail(Assert.java:96)
at org.testng.Assert.failNotEquals(Assert.java:776)
at org.testng.Assert.assertEqualsImpl(Assert.java:137)
at org.testng.Assert.assertEquals(Assert.java:118)
at org.testng.Assert.assertEquals(Assert.java:652)
at org.testng.Assert.assertEquals(Assert.java:662)
at com.eo.tests.PostNewUser.createNewUserIncorrectParamValuesSpecChar_TC007(PostNewUser.java:131)
at java.base/jdk.internal.reflect.NativeMethodAccessorImpl.invoke0(Native Method)
at java.base/jdk.internal.reflect.NativeMethodAccessorImpl.invoke(NativeMethodAccessorImpl.java:62)
at java.base/jdk.internal.reflect.DelegatingMethodAccessorImpl.invoke(DelegatingMethodAccessorImpl.java:43)
at java.base/java.lang.reflect.Method.invoke(Method.java:566)
at org.testng.internal.MethodInvocationHelper.invokeMethod(MethodInvocationHelper.java:124)
at org.testng.internal.Invoker.invokeMethod(Invoker.java:583)
at org.testng.internal.Invoker.invokeTestMethod(Invoker.java:719)
at org.testng.internal.Invoker.invokeTestMethods(Invoker.java:989)
at org.testng.internal.TestMethodWorker.invokeTestMethods(TestMethodWorker.java:125)
at org.testng.internal.TestMethodWorker.run(TestMethodWorker.java:109)
at org.testng.TestRunner.privateRun(TestRunner.java:648)
at org.testng.TestRunner.run(TestRunner.java:505)
at org.testng.SuiteRunner.runTest(SuiteRunner.java:455)
at org.testng.SuiteRunner.runSequentially(SuiteRunner.java:450)
at org.testng.SuiteRunner.privateRun(SuiteRunner.java:415)
at org.testng.SuiteRunner.run(SuiteRunner.java:364)
at org.testng.SuiteRunnerWorker.runSuite(SuiteRunnerWorker.java:52)
at org.testng.SuiteRunnerWorker.run(SuiteRunnerWorker.java:84)
at org.testng.TestNG.runSuitesSequentially(TestNG.java:1208)
at org.testng.TestNG.runSuitesLocally(TestNG.java:1137)
at org.testng.TestNG.runSuites(TestNG.java:1049)
at org.testng.TestNG.run(TestNG.java:1017)
at org.testng.remote.AbstractRemoteTestNG.run(AbstractRemoteTestNG.java:115)
at org.testng.remote.RemoteTestNG.initAndRun(RemoteTestNG.java:251)
at org.testng.remote.RemoteTestNG.main(RemoteTestNG.java:77)
]]>
            </full-stacktrace>
          </exception> <!-- java.lang.AssertionError -->
          <reporter-output>
          </reporter-output>
        </test-method> <!-- createNewUserIncorrectParamValuesSpecChar_TC007 -->
      </class> <!-- com.eo.tests.PostNewUser -->
      <class name="com.eo.tests.GetUsers">
        <test-method is-config="true" signature="setUp()[pri:0, instance:com.eo.tests.GetUsers@6cb6decd]" started-at="2021-01-26T14:22:27Z" name="setUp" finished-at="2021-01-26T14:22:28Z" duration-ms="883" status="PASS">
          <reporter-output>
          </reporter-output>
        </test-method> <!-- setUp -->
        <test-method signature="getUsersValidEP_TC001()[pri:0, instance:com.eo.tests.GetUsers@6cb6decd]" started-at="2021-01-26T14:22:28Z" name="getUsersValidEP_TC001" finished-at="2021-01-26T14:22:32Z" duration-ms="3283" status="PASS">
          <reporter-output>
          </reporter-output>
        </test-method> <!-- getUsersValidEP_TC001 -->
        <test-method is-config="true" signature="setUp()[pri:0, instance:com.eo.tests.GetUsers@6cb6decd]" started-at="2021-01-26T14:22:32Z" name="setUp" finished-at="2021-01-26T14:22:32Z" duration-ms="1" status="PASS">
          <reporter-output>
          </reporter-output>
        </test-method> <!-- setUp -->
        <test-method signature="getUsersCount_TC002()[pri:1, instance:com.eo.tests.GetUsers@6cb6decd]" started-at="2021-01-26T14:22:32Z" name="getUsersCount_TC002" finished-at="2021-01-26T14:22:32Z" duration-ms="143" status="FAIL">
          <exception class="java.lang.AssertionError">
            <message>
              <![CDATA[expected [6] but found [12]]]>
            </message>
            <full-stacktrace>
              <![CDATA[java.lang.AssertionError: expected [6] but found [12]
at org.testng.Assert.fail(Assert.java:96)
at org.testng.Assert.failNotEquals(Assert.java:776)
at org.testng.Assert.assertEqualsImpl(Assert.java:137)
at org.testng.Assert.assertEquals(Assert.java:118)
at org.testng.Assert.assertEquals(Assert.java:652)
at org.testng.Assert.assertEquals(Assert.java:662)
at com.eo.tests.GetUsers.getUsersCount_TC002(GetUsers.java:79)
at java.base/jdk.internal.reflect.NativeMethodAccessorImpl.invoke0(Native Method)
at java.base/jdk.internal.reflect.NativeMethodAccessorImpl.invoke(NativeMethodAccessorImpl.java:62)
at java.base/jdk.internal.reflect.DelegatingMethodAccessorImpl.invoke(DelegatingMethodAccessorImpl.java:43)
at java.base/java.lang.reflect.Method.invoke(Method.java:566)
at org.testng.internal.MethodInvocationHelper.invokeMethod(MethodInvocationHelper.java:124)
at org.testng.internal.Invoker.invokeMethod(Invoker.java:583)
at org.testng.internal.Invoker.invokeTestMethod(Invoker.java:719)
at org.testng.internal.Invoker.invokeTestMethods(Invoker.java:989)
at org.testng.internal.TestMethodWorker.invokeTestMethods(TestMethodWorker.java:125)
at org.testng.internal.TestMethodWorker.run(TestMethodWorker.java:109)
at org.testng.TestRunner.privateRun(TestRunner.java:648)
at org.testng.TestRunner.run(TestRunner.java:505)
at org.testng.SuiteRunner.runTest(SuiteRunner.java:455)
at org.testng.SuiteRunner.runSequentially(SuiteRunner.java:450)
at org.testng.SuiteRunner.privateRun(SuiteRunner.java:415)
at org.testng.SuiteRunner.run(SuiteRunner.java:364)
at org.testng.SuiteRunnerWorker.runSuite(SuiteRunnerWorker.java:52)
at org.testng.SuiteRunnerWorker.run(SuiteRunnerWorker.java:84)
at org.testng.TestNG.runSuitesSequentially(TestNG.java:1208)
at org.testng.TestNG.runSuitesLocally(TestNG.java:1137)
at org.testng.TestNG.runSuites(TestNG.java:1049)
at org.testng.TestNG.run(TestNG.java:1017)
at org.testng.remote.AbstractRemoteTestNG.run(AbstractRemoteTestNG.java:115)
at org.testng.remote.RemoteTestNG.initAndRun(RemoteTestNG.java:251)
at org.testng.remote.RemoteTestNG.main(RemoteTestNG.java:77)
]]>
            </full-stacktrace>
          </exception> <!-- java.lang.AssertionError -->
          <reporter-output>
          </reporter-output>
        </test-method> <!-- getUsersCount_TC002 -->
        <test-method signature="getUsersIncorrectEP_TC003()[pri:2, instance:com.eo.tests.GetUsers@6cb6decd]" started-at="2021-01-26T14:22:32Z" name="getUsersIncorrectEP_TC003" finished-at="2021-01-26T14:22:32Z" duration-ms="101" status="FAIL">
          <exception class="java.lang.AssertionError">
            <message>
              <![CDATA[expected [200] but found [404]]]>
            </message>
            <full-stacktrace>
              <![CDATA[java.lang.AssertionError: expected [200] but found [404]
at org.testng.Assert.fail(Assert.java:96)
at org.testng.Assert.failNotEquals(Assert.java:776)
at org.testng.Assert.assertEqualsImpl(Assert.java:137)
at org.testng.Assert.assertEquals(Assert.java:118)
at org.testng.Assert.assertEquals(Assert.java:652)
at org.testng.Assert.assertEquals(Assert.java:662)
at com.eo.tests.GetUsers.getUsersIncorrectEP_TC003(GetUsers.java:93)
at java.base/jdk.internal.reflect.NativeMethodAccessorImpl.invoke0(Native Method)
at java.base/jdk.internal.reflect.NativeMethodAccessorImpl.invoke(NativeMethodAccessorImpl.java:62)
at java.base/jdk.internal.reflect.DelegatingMethodAccessorImpl.invoke(DelegatingMethodAccessorImpl.java:43)
at java.base/java.lang.reflect.Method.invoke(Method.java:566)
at org.testng.internal.MethodInvocationHelper.invokeMethod(MethodInvocationHelper.java:124)
at org.testng.internal.Invoker.invokeMethod(Invoker.java:583)
at org.testng.internal.Invoker.invokeTestMethod(Invoker.java:719)
at org.testng.internal.Invoker.invokeTestMethods(Invoker.java:989)
at org.testng.internal.TestMethodWorker.invokeTestMethods(TestMethodWorker.java:125)
at org.testng.internal.TestMethodWorker.run(TestMethodWorker.java:109)
at org.testng.TestRunner.privateRun(TestRunner.java:648)
at org.testng.TestRunner.run(TestRunner.java:505)
at org.testng.SuiteRunner.runTest(SuiteRunner.java:455)
at org.testng.SuiteRunner.runSequentially(SuiteRunner.java:450)
at org.testng.SuiteRunner.privateRun(SuiteRunner.java:415)
at org.testng.SuiteRunner.run(SuiteRunner.java:364)
at org.testng.SuiteRunnerWorker.runSuite(SuiteRunnerWorker.java:52)
at org.testng.SuiteRunnerWorker.run(SuiteRunnerWorker.java:84)
at org.testng.TestNG.runSuitesSequentially(TestNG.java:1208)
at org.testng.TestNG.runSuitesLocally(TestNG.java:1137)
at org.testng.TestNG.runSuites(TestNG.java:1049)
at org.testng.TestNG.run(TestNG.java:1017)
at org.testng.remote.AbstractRemoteTestNG.run(AbstractRemoteTestNG.java:115)
at org.testng.remote.RemoteTestNG.initAndRun(RemoteTestNG.java:251)
at org.testng.remote.RemoteTestNG.main(RemoteTestNG.java:77)
]]>
            </full-stacktrace>
          </exception> <!-- java.lang.AssertionError -->
          <reporter-output>
          </reporter-output>
        </test-method> <!-- getUsersIncorrectEP_TC003 -->
        <test-method is-config="true" signature="setUp()[pri:0, instance:com.eo.tests.GetUsers@6cb6decd]" started-at="2021-01-26T14:22:32Z" name="setUp" finished-at="2021-01-26T14:22:32Z" duration-ms="0" status="PASS">
          <reporter-output>
          </reporter-output>
        </test-method> <!-- setUp -->
      </class> <!-- com.eo.tests.GetUsers -->
    </test> <!-- EOAPITest -->
  </suite> <!-- Suite -->
</testng-results>
